<?xml version="1.0" encoding="utf-8"?>

<robot name="rm_65_b">
  <!-- Base cuboid link -->
  <link name="base_cuboid">
    <inertial>
      <origin xyz="0 0 0.2" rpy="0 0 0"/>
      <mass value="1.0"/>
      <inertia ixx="0.01" ixy="0" ixz="0" iyy="0.01" iyz="0" izz="0.01"/>
    </inertial>
    <visual>
      <origin xyz="0 0 0.2" rpy="0 0 0"/>
      <geometry>
        <box size="0.4 0.3 0.4"/>
      </geometry>
      <material name="gray">
        <color rgba="0.5 0.5 0.5 1.0"/>
      </material>
    </visual>
    <collision>
      <origin xyz="0 0 0.2" rpy="0 0 0"/>
      <geometry>
        <box size="0.4 0.3 0.4"/>
      </geometry>
    </collision>
  </link>

  <!-- Fixed joint between base_cuboid and base_link -->
  <joint name="base_cuboid_fixed" type="fixed">
    <parent link="base_cuboid"/>
    <child link="base_link"/>
    <origin xyz="0 0 0.46" rpy="0 -0.7854 -3.1415"/>
  </joint>

  <!-- Dummy base link -->
  <link name="base_link">
    <inertial>
      <origin xyz="-0.000433277303987328 -3.54664423471128E-05 0.0599427668933796" rpy="0 0 0"/>
      <mass value="0.841070778135659"/>
      <inertia ixx="0.0017261110801622" ixy="2.52746264980217E-06" ixz="-3.67690303614961E-05" iyy="0.00170987405835604" iyz="1.67996364994424E-06" izz="0.000904023422915791"/>
    </inertial>
    <visual>
      <origin xyz="0 0 0" rpy="0 0 0"/>
      <geometry>
        <mesh filename="/home/simt-wj/01_Active/tesseract_python/meshes/rm_65_b/base_link.STL"/>
      </geometry>
      <material name="">
        <color rgba="1 1 1 1"/>
      </material>
    </visual>
    <collision>
      <origin xyz="0 0 0" rpy="0 0 0"/>
      <geometry>
        <mesh filename="/home/simt-wj/01_Active/tesseract_python/meshes/rm_65_b/base_link.STL"/>
      </geometry>
    </collision>
  </link>

  <!-- Link 1 -->
  <link name="Link1">
    <inertial>
      <origin xyz="1.2226305431569E-08 0.0211079974844683 -0.0251854220842269" rpy="0 0 0"/>
      <mass value="0.593563443690403"/>
      <inertia ixx="0.00126614120341847" ixy="-1.294980943835E-08" ixz="-9.80120923066996E-09" iyy="0.00118168178300364" iyz="-0.00021121727444415" izz="0.00056135241627747"/>
    </inertial>
    <visual>
      <origin xyz="0 0 0" rpy="0 0 0"/>
      <geometry>
        <mesh filename="/home/simt-wj/01_Active/tesseract_python/meshes/rm_65_b/link1.STL"/>
      </geometry>
      <material name="">
        <color rgba="1 1 1 1"/>
      </material>
    </visual>
    <collision>
      <origin xyz="0 0 0" rpy="0 0 0"/>
      <geometry>
        <mesh filename="/home/simt-wj/01_Active/tesseract_python/meshes/rm_65_b/link1.STL"/>
      </geometry>
    </collision>
  </link>

  <!-- Joint 1 -->
  <joint name="joint1" type="revolute">
    <origin xyz="0 0 0.2405" rpy="0 0 0"/>
    <parent link="base_link"/>
    <child link="Link1"/>
    <axis xyz="0 0 1"/>
    <limit lower="-3.1" upper="3.1" effort="60" velocity="3.14"/>
  </joint>

  <!-- Link 2 -->
  <link name="Link2">
    <inertial>
      <origin xyz="0.152256463426163 4.75383656106654E-07 -0.00620260383607792" rpy="0 0 0"/>
      <mass value="0.864175046869043"/>
      <inertia ixx="0.00089150298478414" ixy="-2.23268489334765E-08" ixz="0.00156246461035015" iyy="0.00733754343083901" iyz="6.28110889329165E-09" izz="0.00697869103915473"/>
    </inertial>
    <visual>
      <origin xyz="0 0 0" rpy="0 0 0"/>
      <geometry>
        <mesh filename="/home/simt-wj/01_Active/tesseract_python/meshes/rm_65_b/link2.STL"/>
      </geometry>
      <material name="">
        <color rgba="1 1 1 1"/>
      </material>
    </visual>
    <collision>
      <origin xyz="0 0 0" rpy="0 0 0"/>
      <geometry>
        <mesh filename="/home/simt-wj/01_Active/tesseract_python/meshes/rm_65_b/link2.STL"/>
      </geometry>
    </collision>
  </link>

  <!-- Joint 2 -->
  <joint name="joint2" type="revolute">
    <origin xyz="0 0 0" rpy="1.5708 -1.5708 0"/>
    <parent link="Link1"/>
    <child link="Link2"/>
    <axis xyz="0 0 1"/>
    <limit lower="-2.268" upper="2.268" effort="60" velocity="3.14"/>
  </joint>

  <!-- Link 3 -->
  <link name="Link3">
    <inertial>
      <origin xyz="5.05312670989961E-06 -0.0595925663694732 0.010569069212336" rpy="0 0 0"/>
      <mass value="0.289633681624654"/>
      <inertia ixx="0.00063737100450158" ixy="-7.05261293649751E-08" ixz="-3.86643272239426E-08" iyy="0.00015648388095025" iyz="-0.00014461035994916" izz="0.000614178164773085"/>
    </inertial>
    <visual>
      <origin xyz="0 0 0" rpy="0 0 0"/>
      <geometry>
        <mesh filename="/home/simt-wj/01_Active/tesseract_python/meshes/rm_65_b/link3.STL"/>
      </geometry>
      <material name="">
        <color rgba="1 1 1 1"/>
      </material>
    </visual>
    <collision>
      <origin xyz="0 0 0" rpy="0 0 0"/>
      <geometry>
        <mesh filename="/home/simt-wj/01_Active/tesseract_python/meshes/rm_65_b/link3.STL"/>
      </geometry>
    </collision>
  </link>

  <!-- Joint 3 -->
  <joint name="joint3" type="revolute">
    <origin xyz="0.256 0 0" rpy="0 0 1.5708"/>
    <parent link="Link2"/>
    <child link="Link3"/>
    <axis xyz="0 0 1"/>
    <limit lower="-2.355" upper="2.355" effort="30" velocity="3.92"/>
  </joint>

  <!-- Link 4 -->
  <link name="Link4">
    <inertial>
      <origin xyz="1.15516617405898E-06 -0.0180424468598241 -0.0215394748352687" rpy="0 0 0"/>
      <mass value="0.239419768320061"/>
      <inertia ixx="0.000285938919722783" ixy="3.07101359163101E-09" ixz="-2.21994118981953E-09" iyy="0.000262727540304212" iyz="4.4236583260078E-05" izz="0.000119888082791859"/>
    </inertial>
    <visual>
      <origin xyz="0 0 0" rpy="0 0 0"/>
      <geometry>
        <mesh filename="/home/simt-wj/01_Active/tesseract_python/meshes/rm_65_b/link4.STL"/>
      </geometry>
      <material name="">
        <color rgba="1 1 1 1"/>
      </material>
    </visual>
    <collision>
      <origin xyz="0 0 0" rpy="0 0 0"/>
      <geometry>
        <mesh filename="/home/simt-wj/01_Active/tesseract_python/meshes/rm_65_b/link4.STL"/>
      </geometry>
    </collision>
  </link>

  <!-- Joint 4 -->
  <joint name="joint4" type="revolute">
    <origin xyz="0 -0.21 0" rpy="1.5708 0 0"/>
    <parent link="Link3"/>
    <child link="Link4"/>
    <axis xyz="0 0 1"/>
    <limit lower="-3.1" upper="3.1" effort="10" velocity="3.92"/>
  </joint>

  <!-- Link 5 -->
  <link name="Link5">
    <inertial>
      <origin xyz="3.19794786262152E-06 -0.0593808368101458 0.00736804250989326" rpy="0 0 0"/>
      <mass value="0.218799761431678"/>
      <inertia ixx="0.000350540363914072" ixy="-3.41781619975602E-08" ixz="-1.77056457224373E-08" iyy="0.000104927867487581" iyz="-7.82431228461971E-05" izz="0.000334482418423629"/>
    </inertial>
    <visual>
      <origin xyz="0 0 0" rpy="0 0 0"/>
      <geometry>
        <mesh filename="/home/simt-wj/01_Active/tesseract_python/meshes/rm_65_b/link5.STL"/>
      </geometry>
      <material name="">
        <color rgba="1 1 1 1"/>
      </material>
    </visual>
    <collision>
      <origin xyz="0 0 0" rpy="0 0 0"/>
      <geometry>
        <mesh filename="/home/simt-wj/01_Active/tesseract_python/meshes/rm_65_b/link5.STL"/>
      </geometry>
    </collision>
  </link>

  <!-- Joint 5 -->
  <joint name="joint5" type="revolute">
    <origin xyz="0 0 0" rpy="-1.5708 0 0"/>
    <parent link="Link4"/>
    <child link="Link5"/>
    <axis xyz="0 0 1"/>
    <limit lower="-2.233" upper="2.233" effort="10" velocity="3.92"/>
  </joint>

  <!-- Link 6 -->
  <link name="Link6">
    <inertial>
      <origin xyz="0.000714234511756999 -0.000396718732824521 -0.0126723660946126" rpy="0 0 0"/>
      <mass value="0.0649018034311231"/>
      <inertia ixx="2.02766547502765E-05" ixy="-1.32505200276849E-06" ixz="-2.5845091522508E-08" iyy="1.87986725225022E-05" iyz="3.39471452125439E-09" izz="3.17885459163081E-05"/>
    </inertial>
    <visual>
      <origin xyz="0 0 0" rpy="0 0 0"/>
      <geometry>
        <mesh filename="/home/simt-wj/01_Active/tesseract_python/meshes/rm_65_b/link6.STL"/>
      </geometry>
      <material name="">
        <color rgba="1 1 1 1"/>
      </material>
    </visual>
    <collision>
      <origin xyz="0 0 0" rpy="0 0 0"/>
      <geometry>
        <mesh filename="/home/simt-wj/01_Active/tesseract_python/meshes/rm_65_b/link6.STL"/>
      </geometry>
    </collision>
  </link>

  <!-- Joint 6 -->
  <joint name="joint6" type="revolute">
    <origin xyz="0 -0.144 0" rpy="1.5708 0 0"/>
    <parent link="Link5"/>
    <child link="Link6"/>
    <axis xyz="0 0 1"/>
    <limit lower="-6.28" upper="6.28" effort="10" velocity="3.92"/>
  </joint>

    <!-- Dummy Gripper -->
  <link name="dummy_gripper">
    <inertial>
      <origin xyz="0 0 0" rpy="0 0 0"/>
      <mass value="0.1"/>
      <inertia ixx="0.001" ixy="0" ixz="0" iyy="0.001" iyz="0" izz="0.001"/>
    </inertial>
    <visual>
      <origin xyz="0 0 0" rpy="0 0 0"/>
      <geometry>
        <cylinder radius="0.06" length="0.2"/>
      </geometry>
      <material name="green">
        <color rgba="0.0 1.0 0.0 0.4"/>
      </material>
    </visual>
    <collision>
      <origin xyz="0 0 0" rpy="0 0 0"/>
      <geometry>
        <cylinder radius="0.06" length="0.2"/>
      </geometry>
    </collision>
  </link>

  <joint name="joint_gripper_fixed" type="fixed">
    <parent link="Link6"/>
    <child link="dummy_gripper"/>
    <origin xyz="0 0 0.11" rpy="0 0 0"/>
  </joint>

  <!-- TCP link and joint (uncomment if needed) -->
  <link name="dummy_tcp">
    <inertial>
      <origin xyz="0.0 0.0 0.0" rpy="0 0 0"/>
      <mass value="0.7"/>
      <inertia ixx="1.0E-03" ixy="1.0E-06" ixz="1.0E-06" iyy="1.0E-03" iyz="1.0E-06" izz="1.0E-03"/>
    </inertial>
    <visual>
      <origin xyz="0 0 0" rpy="0 0 0"/>
      <geometry>
        <box size="0.01 0.01 0.01"/>
      </geometry>
      <material name="">
        <color rgba="0.3 0.3 0.3 1.0"/>
      </material>
    </visual>
    <!-- X Axis -->
    <visual>
      <origin xyz="0.05 0 0" rpy="0 1.5708 0"/>
      <geometry>
        <cylinder radius="0.005" length="0.1"/>
      </geometry>
      <material name="red">
        <color rgba="1.0 0.0 0.0 1.0"/>
      </material>
    </visual>
    <!-- Y Axis -->
    <visual>
      <origin xyz="0 0.05 0" rpy="1.5708 0 0"/>
      <geometry>
        <cylinder radius="0.005" length="0.1"/>
      </geometry>
      <material name="green_axis">
        <color rgba="0.0 1.0 0.0 1.0"/>
      </material>
    </visual>
    <!-- Z Axis -->
    <visual>
      <origin xyz="0 0 0.05" rpy="0 0 0"/>
      <geometry>
        <cylinder radius="0.005" length="0.1"/>
      </geometry>
      <material name="blue">
        <color rgba="0.0 0.0 1.0 1.0"/>
      </material>
    </visual>
    <collision>
      <origin xyz="0 0 0" rpy="0 0 0"/>
      <geometry>
        <box size="0.05 0.05 0.05"/>
      </geometry>
    </collision>
  </link>
  <joint name="joint_tcp_fixed" type="fixed">
    <parent link="dummy_gripper"/>
    <child link="dummy_tcp"/>
    <origin xyz="0 0 0.11" rpy="0 0 0"/>
  </joint>
</robot>
